Workbook
Name Param.Startjahr: Parameter!$F$6
Name Param.Startalter: Parameter!$F$8
Name Param.DeportwertStart: Parameter!$F$31
Name Param.SparrateDepotMonatl: Parameter!$F$18
Name Param.SparrateFestgeldMonatl: Parameter!$F$19
Name Param.DeportwertStartPerformAnteil: Parameter!$F$32
Name Param.Teilfreistellung: Parameter!$F$12
Name Param.FireStartjahr: Parameter!$F$9
Name Param.SonstigEinmaligBeschreib1: Parameter!$C$67
Name Param.SonstigEinmaligBeschreib2: Parameter!$C$68
Name Param.SonstigEinmaligBeschreib3: Parameter!$C$69
Name Param.SonstigEinmaligBeschreib4: Parameter!$C$70
Name Param.SonstigEinmaligBeschreib5: Parameter!$C$71
Name Param.SonstigEinmaligBeschreib6: Parameter!$C$72
Name Param.SonstigEinmaligBeschreib7: Parameter!$C$73
Name Param.SonstigEinmaligBeschreib8: Parameter!$C$74
Name Param.SonstigEinmaligBeschreib9: Parameter!$C$75
Name Param.SonstigEinmaligBeschreib10: Parameter!$C$76
Name Param.FestgeldStart: Parameter!$F$44
Name Param.FestgeldZinssatz: Parameter!$F$45
Name Param.SparerPauschbetrag: Parameter!$F$13
Name Param.SonstigEinmaligBetrag1: Parameter!$D$67
Name Param.SonstigEinmaligBetrag2: Parameter!$D$68
Name Param.SonstigEinmaligBetrag3: Parameter!$D$69
Name Param.SonstigEinmaligBetrag4: Parameter!$D$70
Name Param.SonstigEinmaligBetrag5: Parameter!$D$71
Name Param.SonstigEinmaligBetrag6: Parameter!$D$72
Name Param.SonstigEinmaligBetrag7: Parameter!$D$73
Name Param.SonstigEinmaligBetrag8: Parameter!$D$74
Name Param.SonstigEinmaligBetrag9: Parameter!$D$75
Name Param.SonstigEinmaligBetrag10: Parameter!$D$76
Name Param.SonstigEinmaligJahr1: Parameter!$E$67
Name Param.SonstigEinmaligJahr2: Parameter!$E$68
Name Param.SonstigEinmaligJahr3: Parameter!$E$69
Name Param.SonstigEinmaligJahr4: Parameter!$E$70
Name Param.SonstigEinmaligJahr5: Parameter!$E$71
Name Param.SonstigEinmaligJahr6: Parameter!$E$72
Name Param.SonstigEinmaligJahr7: Parameter!$E$73
Name Param.SonstigEinmaligJahr8: Parameter!$E$74
Name Param.SonstigEinmaligJahr9: Parameter!$E$75
Name Param.SonstigEinmaligJahr10: Parameter!$E$76
Name Param.SonstigRegelmJahrBeginn10: Parameter!$G$62
Name Param.SonstigRegelmBeschreib1: Parameter!$C$53
Name Param.SonstigRegelmBeschreib2: Parameter!$C$54
Name Param.SonstigRegelmBeschreib3: Parameter!$C$55
Name Param.SonstigRegelmBeschreib4: Parameter!$C$56
Name Param.SonstigRegelmBeschreib5: Parameter!$C$57
Name Param.SonstigRegelmBeschreib6: Parameter!$C$58
Name Param.SonstigRegelmBeschreib7: Parameter!$C$59
Name Param.SonstigRegelmBeschreib8: Parameter!$C$60
Name Param.SonstigRegelmBeschreib9: Parameter!$C$61
Name Param.SonstigRegelmBeschreib10: Parameter!$C$62
Name Param.SonstigRegelmBetragJaehrl1: Parameter!$E$53
Name Param.SonstigRegelmBetragJaehrl2: Parameter!$E$54
Name Param.SonstigRegelmBetragJaehrl3: Parameter!$E$55
Name Param.SonstigRegelmBetragJaehrl4: Parameter!$E$56
Name Param.SonstigRegelmBetragJaehrl5: Parameter!$E$57
Name Param.SonstigRegelmBetragJaehrl6: Parameter!$E$58
Name Param.SonstigRegelmBetragJaehrl7: Parameter!$E$59
Name Param.SonstigRegelmBetragJaehrl8: Parameter!$E$60

Sheet Parameter
B1: FiRe-Spread - Beta | M1: v0.3.3
H2: =_xlfn.CONCAT(G37:G41)
F3: Graue Felder nicht bearbeiten (werden autom. berechnet)
C4: Grunddaten | H4: Ergebnis
C5: Jahresangaben | H5: In Zahlen
C6: Startjahr der Simulation | F6: 2026 | H6: Vermögen reicht bis ins Jahr: | K6: =IF(MIN(FIRE!BM5:BM100)=0,"bis ans Lebensende (~unendlich)",MIN(FIRE!BM5:BM100)-1) -> 2078 | R6: Ziel dieses Tools
C7: Monat der Vermögenserfassung | F7: 6 | H7: Vermögen reicht bis ins Lebensjahr: | K7: =IF(MIN(FIRE!BM5:BM100)=0,"bis ans Lebensende (~unendlich)",MIN(FIRE!BM5:BM100)-Param.Startjahr+Param.Startalter-1) -> 82 | R7: Errechnet wie lange das Vermögen bei vorgegebenden Sparrate und Entnahme ausreicht und berücksichtigt sonstige regelm. und einmalige Einzahlungen und Ausgaben.
C8: Alter zum Startjahr der Simulation | F8: 30 | H8: =IF(FIRE!BJ1<>"Festgeld positiv","Das Festgeld läuft irgendwann ins negative - Zu hohe einmalige Festgeld-Ausgabe geplant?",IF(_xlfn.CONCAT(G37:G41,N67:N76)<>"","Es besteht ein Fehler in diesem Tabellenblatt - siehe Zeile neben dem Begriff ""[Fehler]"" innerhalb dieses Tabellenblatts.","")) | R8: Depot und Festgeld verschiedene Rendite
C9: FIRE-Startjahr | F9: 2045 | R9: Die Entnahme erfolgt immer aus dem Depot _und_ dem Festgeld. Immer proportional zum jeweiligen Bestand. So leeren sich beide Konten synchron und sollten ungefähr zeitgleich leer sein.
H10: In Worten | R10: Sonstige Lebensereignisse werden berücksichtigt (z.B. Auszahlung von privaten Lebensversicherungen, staatl. Rentenzahlung)
C11: Erwartete Steuern + Inflation | H11: =IF(Param.FireStartjahr=Param.Startjahr,"Wenn du direkt im Startjahr in die Entnahmephase gehst (kein Ansparjahr),","Wenn du mit den angegebenen Parametern bis zum Jahr "&Param.FireStartjahr-1&" jährlich "&TEXT(Param.SparrateGesamtJaehrlich,"#.##0")&"€ einzahlst und im Dezember "&Param.FireStartjahr-1&" aufhörst zu arbeiten/einzuzahlen,")&" steht dir ab Januar "&Param.FireStartjahr&" "&IF(MIN(FIRE!BM5:BM100)=0,"bis ans Lebensende (~unendlich)","bis ins Jahr "&MIN(FIRE!BM5:BM100)-1&" (Alter: "&MIN(FIRE!BM5:BM100)-Param.Startjahr+Param.Startalter-1&")")&" jährlich "&TEXT(Param.EntnahmeBetragStart,"#.##0")&"€ (real) zur Verfügung"&IF(MIN(FIRE!BM5:BM100)=0," (dann gibt es auch noch Restkapital)."," (= Pleite im Alter von "&MIN(FIRE!BM5:BM100)-Param.Startjahr+Param.Startalter&").") -> Wenn du mit den angegebenen Parametern bis zum Jahr 2044 jährlich 7.800€ einzahlst und im Dezember 2044 aufhörst zu arbeiten/einzuzahlen, steht dir ab Januar 2045 bis ins Jahr 2078 (Alter: 82) jährlich 30.000€ (real) zur Verfügung (= Pleite im Alter von 83). | R11: Nachvollziehbare Berechnung mit Möglichkeit zur Meldung/Korrektur von Fehlern (in Online-Tools nicht immer möglich)
C12: Teilfreistellung Depot | F12: 0.3 | R12: Annäherung: Versteuerung den Entnahmen unter Berücksichtigung des Sparer-Pauschbetrag (_keine_ Günstigerprüfung!)
C13: Sparer Pauschbetrag | F13: 1000 | R13: Möglichkeit zur Simulation von der Depotentwicklung in frei wählbaren Rendite-starken/-schwachen Jahren.
C14: KapSt (inkl Soli) | F14: =0.25*1.055 -> 0.26375 | R14: Eine SWR wird nicht berechnet oder berücksichtigt.
C15: Inflationsrate p.a. | F15: 0.025
R16: Anforderungen
C17: Einzahlungen bis Rentenbeginn | R17: keine Makros
C18: Depot - Sparrate monatlich | F18: 500 | R18: Läuft in
C19: Festgeld - Sparrate monatlich | F19: 150 | R19: Planmaker (Softmaker)
C20: Dynamische Anpassung der Sparrate in % (jährl. Erhöhung gilt für Depot und Festgeld) | F20: 0 | R20: LibreCalc (LibreOffice)
C21: Gesamtsparrate - monatlich (im 1. Jahr / wird in Folgejahren u.U.dynamisch erhöht) | F21: =Param.SparrateDepotMonatl+Param.SparrateFestgeldMonatl -> 650 | R21: Wahrscheinlich auch in Excel (MS Office)
C22: Gesamtsparrate - jährlich (im 1. Jahr / wird in Folgejahren u.U. dynamisch erhöht) | F22: =F21*12 -> 7800
R23: Annahmen / Rechnerverhalten
C24: Entnahmeplan ab Rentenbeginn | R24: - Depotentwicklung wird berechnet unter Annahme, dass die Entnahme (während Entnahmephasen) jeweils zum Jahresbeginn erfolgt. Die Einzahlung/Verzinsung (während Ansparphase) erfolgt monatlich.
C25: Jährliche Entnahme (real im heutigen Jahr) | F25: 30000 | R25: - Vereinfachung: Die sonstigen regelm. / einmaligen Einkünfte und Ausgaben werden berücksichtig, wie eine Bewegung zum jeweiligen Jahrebeginn (auch wenn z.B. die regelm. Einkunft "staatl. Rente" monatlich erfolgt).
C26: Jährliche Entnahme (real zum 1. Entnahmejahr) | F26: =F25*(1+F15)^(F9-F6) -> 47959.506 | R26: - Sparer-Freibetrag wird immer zuerst von den Festgelderträgen abgezogen (auch wenn keine Entnahme erfolgt). Wenn die Erträge auf Festgeld kleiner sind als der Sparerpauschbetrag (z.B. 1.000€) wird der Rest des Sparerpauschbetrags von der steuerpflicht der Depoterträge abgezogen.
R27: - Entnahme aus Depot und Festgeld ist immer proportial zum jeweiligen Depot-/Kontowert
R28: - mit "Festgeldkonto" ist ein beliebiges Konto gemeint (egal. ob Giro/Tagesgeld/Festgeldkonto). Es könnte auch ein Depot mit Geldmarkt-ETF (=ohne Teilfreistellung) sein, das relativ konstante Rendite/Zins abwirft.
C29: Vermögen zum Beginn des Startjahres der Simulation
C30: Depot | R30: Nicht berücksichtigt:
C31: Depotwert Start € | F31: 300000 | R31: - keine Günstigerprüfung (https://frugalisten.de/steuern-kapitalertraege-privatier-optimieren/)
C32: Davon Performance (Gewinn vom Gesamtdepotwert) | F32: 120000 | R32: - FiFo-Prinzip beim Verkauf von Wertpapieranteilen wird nicht berücksichtigt
C33: Bisherige Depot-Performance in % | F33: =IFERROR(F32/(F31-F32),0) -> 0.66666667 | R33: - keine Berücksichtigung des Renditereihenfolgerisikos / Sequence of Returns Risk (über "Außergewöhnliche Renditen" kann stark vereinfacht "gespielt"/"simuliert" werden)
C34: Depot-Renditeerwartung jährlich (nominal) | R34: - keine Monte Carlo Simulation
C35: Erwartete "Standard-Rendite" (nominal) | F35: 0.06 | R35: - Vorabpauschale wird nicht berücksichtigt
C36: Optional [!] - Außergewöhnliche Renditen (nominal) | D36: Beginn | E36: Ende | F36: %
C37: Schwache Globalwirtschaft | D37: 2026 | E37: 2028 | F37: 0.03 | G37: =IF(Param.DepotRenditeSpezBeginn1>Param.DepotRenditeSpezEnde1,"[Fehler]","") | R37: Verbesserungspotential
C38: Schleppende Erhohlung | D38: 2030 | E38: 2033 | F38: 0.04 | G38: =IF(AND(Param.DepotRenditeSpezBeginn2&Param.DepotRenditeSpezEnde2<>"",OR(Param.DepotRenditeSpezBeginn2<=Param.DepotRenditeSpezEnde1,Param.DepotRenditeSpezEnde2<Param.DepotRenditeSpezBeginn2)),"[Fehler]","") | R38: Überprüfen ob überall die richtigen Begriffe verwendet wurden (z.B. Performance vs Gewinnanteil, Nominal vs Real, Brutto vs Netto)
C39: Starke Jahre | D39: 2045 | E39: 2047 | F39: 0.07 | G39: =IF(AND(Param.DepotRenditeSpezBeginn3&Param.DepotRenditeSpezEnde3<>"",OR(Param.DepotRenditeSpezBeginn3<=MAX(E37:E38),Param.DepotRenditeSpezEnde3<Param.DepotRenditeSpezBeginn3)),"[Fehler]","") | R39: Überprüfen der Berechnungen
G40: =IF(AND(Param.DepotRenditeSpezBeginn4&Param.DepotRenditeSpezEnde4<>"",OR(Param.DepotRenditeSpezBeginn4<=MAX(E37:E39),Param.DepotRenditeSpezEnde4<Param.DepotRenditeSpezBeginn4)),"[Fehler]","") | R40: Im Speziellen die Berechnung in den folgenden Spalten überprüfen:
...

Sheet FIRE
U1: ist die Einzahlung korrekt in den Gewinnanteil eingerechnet? | AO1: ="Die _jährliche_ Standard-Rendite von "&Param.DepotRenditeDefault*100&"% entspricht einer _monatlichen_ Rendite von "&ROUND(((1+Param.DepotRenditeDefault)^(1/12)-1)*100,2)&"%." -> Die _jährliche_ Standard-Rendite von 6% entspricht einer _monatlichen_ Rendite von 0,49%. | BJ1: =IF(MIN(BJ5:BJ90)<0,"Festgeld negativ","Festgeld positiv") -> Festgeld positiv | BM1: Vermögen reicht bis:
D2: sonstige regelm. Einkünfte (z.B. Mieten) und Ausgaben (z.B. KV) - außerhalb d. norm. Ansparphase/Entnahmeplans | S2: Depot | AP2: Festgeld | BM2: ="Jahr: "&IF(MIN(BM5:BM100)=0,"unendlich",MIN(BM5:BM100)-1&" (Unzureichend ab: "&MIN(BM5:BM100))&")" -> Jahr: 2078 (Unzureichend ab: 2079) | BR2: macht keinen Sinn, wenn die "gesamte entnahme" negativ ist (z.B. wenn eine hohe Lebensverscherung ausgezahlt wurde)
P3: Vermögensaufteilung | V3: sonstige einmalige Einzahlungen ins Depot - außerhalb d. norm. Ansparphase | AS3: sonstige einmalige Einkünfte (z.B. Auszahlung Lebensvers.) und Ausgaben (z.B. Autokauf) - außerhalb d. norm. Ansparphase/Entnahmeplans | BM3: ="Alter: "&MIN(FIRE!BM5:BM100)-Param.Startjahr+Param.Startalter-1 -> Alter: 82
A4: Jahr | B4: Alter | C4: benötigtes Kapital (real) (zum ausgeben, gemäß Entnahmeplan) | D4: =Param.SonstigRegelmBeschreib1 -> Staatl. Rente (erwarteter Betrag im 1. Jahr der Rentenzahlung) | E4: =Param.SonstigRegelmBeschreib2 -> Krankenversicherung (KV) | F4: =Param.SonstigRegelmBeschreib3 -> Mieteinkunft | G4: =Param.SonstigRegelmBeschreib4 -> 0 | H4: =Param.SonstigRegelmBeschreib5 -> 0 | I4: =Param.SonstigRegelmBeschreib6 -> 0 | J4: =Param.SonstigRegelmBeschreib7 -> 0 | K4: =Param.SonstigRegelmBeschreib8 -> 0 | L4: =Param.SonstigRegelmBeschreib9 -> 0 | M4: =Param.SonstigRegelmBeschreib10 -> 0 | N4: benötigte Entnahme (nach Berücksichtigung der sonst. regelm. Einkünfte/Ausgaben) | O4: Überschuss aus sonstigen Einkünften/Ausgaben (falls Einkünfte höher benötigtes Kapital) | P4: Gesamtvermögen (vor Entnahme) | Q4: % Depot | R4: % Festgeld | S4: Depot Start | T4: Gewinnanteil am Depotwert | U4: Depot - jährl. Einzahlung während Ansparphase | V4: =IF(Param.SonstigEinmaligKonto1="Depot",Param.SonstigEinmaligBeschreib1,"") | W4: =IF(Param.SonstigEinmaligKonto2="Depot",Param.SonstigEinmaligBeschreib2,"") | X4: =IF(Param.SonstigEinmaligKonto3="Depot",Param.SonstigEinmaligBeschreib3,"") | Y4: =IF(Param.SonstigEinmaligKonto4="Depot",Param.SonstigEinmaligBeschreib4,"") | Z4: =IF(Param.SonstigEinmaligKonto5="Depot",Param.SonstigEinmaligBeschreib5,"") | AA4: =IF(Param.SonstigEinmaligKonto6="Depot",Param.SonstigEinmaligBeschreib6,"") | AB4: =IF(Param.SonstigEinmaligKonto7="Depot",Param.SonstigEinmaligBeschreib7,"") | AC4: =IF(Param.SonstigEinmaligKonto8="Depot",Param.SonstigEinmaligBeschreib8,"") | AD4: =IF(Param.SonstigEinmaligKonto9="Depot",Param.SonstigEinmaligBeschreib9,"") | AE4: =IF(Param.SonstigEinmaligKonto10="Depot",Param.SonstigEinmaligBeschreib10,"") | AF4: Verfügbarer Pauschbetrag (nach versteuerung von Festgeldzins) | AG4: Depot - benötigte Entnahme ohne KapErtrgSteuern | AH4: Depot - benötigte Entnahme inkl. KapErtrgSteuern | AI4: Steuer | AJ4: Gewinn nach Entnahme | AK4: Depotwert nach Entnahme | AL4: Depotwert nach Rendite inkl. Einzahlungen | AM4: Gewinn nach Rendite | AN4: Gewinnquote | AO4: Monatlicher Zinssatz (umgerechnet "erwarteter Rendite") | AP4: Festgeld Start | AQ4: Festgeld - Einzahlung während Ansparphase | AR4: Einzahlung aus Überschuss aus regelm. Einkünften | AS4: =IF(Param.SonstigEinmaligKonto1="Festgeld",Param.SonstigEinmaligBeschreib1,"") -> Auszahlung Kapitallebensversicherung (Einmalzahlung) | AT4: =IF(Param.SonstigEinmaligKonto2="Festgeld",Param.SonstigEinmaligBeschreib2,"") -> Autokauf | AU4: =IF(Param.SonstigEinmaligKonto3="Festgeld",Param.SonstigEinmaligBeschreib3,"") -> Verkauf Immobilie | AV4: =IF(Param.SonstigEinmaligKonto4="Festgeld",Param.SonstigEinmaligBeschreib4,"") | AW4: =IF(Param.SonstigEinmaligKonto5="Festgeld",Param.SonstigEinmaligBeschreib5,"") | AX4: =IF(Param.SonstigEinmaligKonto6="Festgeld",Param.SonstigEinmaligBeschreib6,"") | AY4: =IF(Param.SonstigEinmaligKonto7="Festgeld",Param.SonstigEinmaligBeschreib7,"") | AZ4: =IF(Param.SonstigEinmaligKonto8="Festgeld",Param.SonstigEinmaligBeschreib8,"") | BA4: =IF(Param.SonstigEinmaligKonto9="Festgeld",Param.SonstigEinmaligBeschreib9,"") | BB4: =IF(Param.SonstigEinmaligKonto10="Festgeld",Param.SonstigEinmaligBeschreib10,"") | BC4: Festgeld Entnahme für Entnahmeplan (keine "sonstige Einkunft/Ausgabe") | BD4: Rendite % | BE4: Brutto Zinsen | BF4: Genutzter Pauschbetrag | BG4: Nach Pausch. | BH4: Steuer | BI4: Netto Zinsen | BJ4: Festgeld Ende inkl. Zinsen (nach Einzahl. & Entnahme) | BK4: Gesamtverm. € | BL4: Gesamtverm. real € | BM4: Jahr in dem das Gesamtvermögen _nicht_ mehr für die geplante Entnahme reicht | BN4: Gesamte geplante + regelm. Entnahmen (aus Depot & Festgeldkonto) | BO4: sonstige einmalige Einkünft & Ausgaben | BP4: Gesamte Entnahmen | BQ4: Gezahlte Steuern (auf Depot und Festgeld) | BR4: Entnahmerate / Withdrawing rate
A5: =Parameter!F6 -> 2026 | B5: =Param.Startalter -> 30 | C5: =IF(A5<Param.FireStartjahr,0,Param.EntnahmeBetragStart*(1+Param.Inflationsrate)^(A5-Param.Startjahr)) -> 0 | D5: =IF(OR($A5<Param.SonstigRegelmJahrBeginn1,$A5>Param.SonstigRegelmJahrEnd1),0,Param.SonstigRegelmBetragJaehrl1*(1+Param.SonstigRegelmSteig1)^(A5-Param.SonstigRegelmJahrBeginn1)) -> 0 | E5: =IF(OR($A5<Param.SonstigRegelmJahrBeginn2,$A5>Param.SonstigRegelmJahrEnd2),0,Param.SonstigRegelmBetragJaehrl2*(1+Param.SonstigRegelmSteig2)^($A5-Param.SonstigRegelmJahrBeginn2)) -> 0 | F5: =IF(OR($A5<Param.SonstigRegelmJahrBeginn3,$A5>Param.SonstigRegelmJahrEnd3),0,Param.SonstigRegelmBetragJaehrl3*(1+Param.SonstigRegelmSteig3)^($A5-Param.SonstigRegelmJahrBeginn3)) -> 0 | G5: =IF(OR($A5<Param.SonstigRegelmJahrBeginn4,$A5>Param.SonstigRegelmJahrEnd4),0,Param.SonstigRegelmBetragJaehrl4*(1+Param.SonstigRegelmSteig4)^($A5-Param.SonstigRegelmJahrBeginn4)) -> 0 | H5: =IF(OR($A5<Param.SonstigRegelmJahrBeginn5,$A5>Param.SonstigRegelmJahrEnd5),0,Param.SonstigRegelmBetragJaehrl5*(1+Param.SonstigRegelmSteig5)^($A5-Param.SonstigRegelmJahrBeginn5)) -> 0 | I5: =IF(OR($A5<Param.SonstigRegelmJahrBeginn6,$A5>Param.SonstigRegelmJahrEnd6),0,Param.SonstigRegelmBetragJaehrl6*(1+Param.SonstigRegelmSteig6)^($A5-Param.SonstigRegelmJahrBeginn6)) -> 0 | J5: =IF(OR($A5<Param.SonstigRegelmJahrBeginn7,$A5>Param.SonstigRegelmJahrEnd7),0,Param.SonstigRegelmBetragJaehrl7*(1+Param.SonstigRegelmSteig7)^($A5-Param.SonstigRegelmJahrBeginn7)) -> 0 | K5: =IF(OR($A5<Param.SonstigRegelmJahrBeginn8,$A5>Param.SonstigRegelmJahrEnd8),0,Param.SonstigRegelmBetragJaehrl8*(1+Param.SonstigRegelmSteig8)^($A5-Param.SonstigRegelmJahrBeginn8)) -> 0 | L5: =IF(OR($A5<Param.SonstigRegelmJahrBeginn9,$A5>Param.SonstigRegelmJahrEnd9),0,Param.SonstigRegelmBetragJaehrl9*(1+Param.SonstigRegelmSteig9)^($A5-Param.SonstigRegelmJahrBeginn9)) -> 0 | M5: =IF(OR($A5<Param.SonstigRegelmJahrBeginn10,$A5>Param.SonstigRegelmJahrEnd10),0,Param.SonstigRegelmBetragJaehrl10*(1+Param.SonstigRegelmSteig10)^($A5-Param.SonstigRegelmJahrBeginn10)) -> 0 | N5: =MAX(0,C5-SUM(D5:M5)) -> 0 | O5: =IF(N5<=0,SUM(D5:M5)-C5,0) -> 0 | P5: =S5+AP5 -> 400000 | Q5: =IF(P5>0,S5/P5,0) -> 0.75 | R5: =IF(P5>0,AP5/P5,0) -> 0.25 | S5: =Param.DeportwertStart -> 300000 | T5: =Param.DeportwertStartPerformAnteil -> 120000 | U5: =IF(A5<Param.FireStartjahr,Param.SparrateDepotMonatl*(13-Param.StartmonatVermoegensstand)*(1+Param.SparrateDynamikJaehrl)^($A5-Param.Startjahr),0) -> 3500 | V5: =IF(AND(Param.SonstigEinmaligKonto1="Depot",$A5=Param.SonstigEinmaligJahr1),Param.SonstigEinmaligBetrag1,0) -> 0 | W5: =IF(AND(Param.SonstigEinmaligKonto2="Depot",$A5=Param.SonstigEinmaligJahr2),Param.SonstigEinmaligBetrag2,0) -> 0 | X5: =IF(AND(Param.SonstigEinmaligKonto3="Depot",$A5=Param.SonstigEinmaligJahr3),Param.SonstigEinmaligBetrag3,0) -> 0 | Y5: =IF(AND(Param.SonstigEinmaligKonto4="Depot",$A5=Param.SonstigEinmaligJahr4),Param.SonstigEinmaligBetrag4,0) -> 0 | Z5: =IF(AND(Param.SonstigEinmaligKonto5="Depot",$A5=Param.SonstigEinmaligJahr5),Param.SonstigEinmaligBetrag5,0) -> 0 | AA5: =IF(AND(Param.SonstigEinmaligKonto6="Depot",$A5=Param.SonstigEinmaligJahr6),Param.SonstigEinmaligBetrag6,0) -> 0 | AB5: =IF(AND(Param.SonstigEinmaligKonto7="Depot",$A5=Param.SonstigEinmaligJahr7),Param.SonstigEinmaligBetrag7,0) -> 0 | AC5: =IF(AND(Param.SonstigEinmaligKonto8="Depot",$A5=Param.SonstigEinmaligJahr8),Param.SonstigEinmaligBetrag8,0) -> 0 | AD5: =IF(AND(Param.SonstigEinmaligKonto9="Depot",$A5=Param.SonstigEinmaligJahr9),Param.SonstigEinmaligBetrag9,0) -> 0 | AE5: =IF(AND(Param.SonstigEinmaligKonto10="Depot",$A5=Param.SonstigEinmaligJahr10),Param.SonstigEinmaligBetrag10,0) -> 0 | AF5: =Param.SparerPauschbetrag-BF5 -> 0 | AG5: =IF(AND(A5>=Param.FireStartjahr,S5>0),MIN(N5*Q5,S5),0) -> 0 | AH5: =IF(AG5<=0,0,IF(S5<=0,0,AG5/(1-MAX(0,((T5/S5)*(1-Param.Teilfreistellung)-MIN(AF5,AG5)/AG5)*Param.KapSt)))) -> 0 | AI5: =AH5-AG5 -> 0 | AJ5: =T5-AH5*(T5/S5) -> 120000 | AK5: =S5-AH5 -> 300000 | AL5: =FV(AO5,(13-Param.StartmonatVermoegensstand),-(U5/(13-Param.StartmonatVermoegensstand)),-AK5,0) -> 308743.65 | AM5: =AJ5+AL5-AK5-U5 -> 125243.65 | AN5: =AM5/AL5 -> 0.40565579 | AO5: =(1+IF(AND(A5>=Param.DepotRenditeSpezBeginn1,A5<=Param.DepotRenditeSpezEnde1),Param.DepotRenditeSpezProz1,IF(AND(A5>=Param.DepotRenditeSpezBeginn2,A5<=Param.DepotRenditeSpezEnde2),Param.DepotRenditeSpezProz2,IF(AND(A5>=Param.DepotRenditeSpezBeginn3,A5<=Param.DepotRenditeSpezEnde3),Param.DepotRenditeSpezProz3,IF(AND(A5>=Param.DepotRenditeSpezBeginn4,A5<=Param.DepotRenditeSpezEnde4),Param.DepotRenditeSpezProz4,IF(AND(A5>=Param.DepotRenditeSpezBeginn5,A5<=Param.DepotRenditeSpezEnde5),Param.DepotRenditeSpezProz5,Param.DepotRenditeDefault))))))^(1/12)-1 -> 0.0024662698 | AP5: =Param.FestgeldStart -> 100000 | AQ5: =IF(A5<Param.FireStartjahr,Param.SparrateFestgeldMonatl*(13-Param.StartmonatVermoegensstand)*(1+Param.SparrateDynamikJaehrl)^($A5-Param.Startjahr),0) -> 1050 | AR5: =O5 -> 0 | AS5: =IF(AND(Param.SonstigEinmaligKonto1="Festgeld",$A5=Param.SonstigEinmaligJahr1),Param.SonstigEinmaligBetrag1,0) -> 0 | AT5: =IF(AND(Param.SonstigEinmaligKonto2="Festgeld",$A5=Param.SonstigEinmaligJahr2),Param.SonstigEinmaligBetrag2,0) -> 0 | AU5: =IF(AND(Param.SonstigEinmaligKonto3="Festgeld",$A5=Param.SonstigEinmaligJahr3),Param.SonstigEinmaligBetrag3,0) -> 0 | AV5: =IF(AND(Param.SonstigEinmaligKonto4="Festgeld",$A5=Param.SonstigEinmaligJahr4),Param.SonstigEinmaligBetrag4,0) -> 0 | AW5: =IF(AND(Param.SonstigEinmaligKonto5="Festgeld",$A5=Param.SonstigEinmaligJahr5),Param.SonstigEinmaligBetrag5,0) -> 0 | AX5: =IF(AND(Param.SonstigEinmaligKonto6="Festgeld",$A5=Param.SonstigEinmaligJahr6),Param.SonstigEinmaligBetrag6,0) -> 0 | AY5: =IF(AND(Param.SonstigEinmaligKonto7="Festgeld",$A5=Param.SonstigEinmaligJahr7),Param.SonstigEinmaligBetrag7,0) -> 0 | AZ5: =IF(AND(Param.SonstigEinmaligKonto8="Festgeld",$A5=Param.SonstigEinmaligJahr8),Param.SonstigEinmaligBetrag8,0) -> 0 | BA5: =IF(AND(Param.SonstigEinmaligKonto9="Festgeld",$A5=Param.SonstigEinmaligJahr9),Param.SonstigEinmaligBetrag9,0) -> 0 | BB5: =IF(AND(Param.SonstigEinmaligKonto10="Festgeld",$A5=Param.SonstigEinmaligJahr10),Param.SonstigEinmaligBetrag10,0) -> 0 | BC5: =IF(AND(A5>=Param.FireStartjahr,AP5>0),MIN(N5*R5,AP5),0) -> 0 | BD5: =Param.FestgeldZinssatz -> 0.02 | BE5: =(AP5+SUM(AQ5:BB5)-BC5)*BD5*(13-Param.StartmonatVermoegensstand)/12 -> 1178.9167 | BF5: =IF(BE5>Param.SparerPauschbetrag,Param.SparerPauschbetrag,BE5) -> 1000 | BG5: =BE5-BF5 -> 178.91667 | BH5: =BG5*Param.KapSt -> 47.189271 | BI5: =BE5-BH5 -> 1131.7274 | BJ5: =AP5+SUM(AQ5:BB5)-BC5+BI5 -> 102181.73 | BK5: =AL5+BJ5 -> 410925.37 | BL5: =BK5/(1+Param.Inflationsrate)^(A5-Param.Startjahr) -> 410925.37 | BM5: =IF(BK5<N5,A5,"") | BN5: =AH5+BC5 -> 0 | BO5: =SUM(AR5:BB5) -> 0 | BP5: =BN5+(-1*BO5) -> 0 | BQ5: =AI5+BH5 -> 47.189271 | BR5: =IF(BK5>0,BP5/BK5,0) -> 0
A6: =A5+1 -> 2027 | B6: =B5+(2-1) -> 31 | C6: =IF(A6<Param.FireStartjahr,0,Param.EntnahmeBetragStart*(1+Param.Inflationsrate)^(A6-Param.Startjahr)) -> 0 | D6: =IF(OR($A6<Param.SonstigRegelmJahrBeginn1,$A6>Param.SonstigRegelmJahrEnd1),0,Param.SonstigRegelmBetragJaehrl1*(1+Param.SonstigRegelmSteig1)^(A6-Param.SonstigRegelmJahrBeginn1)) -> 0 | E6: =IF(OR($A6<Param.SonstigRegelmJahrBeginn2,$A6>Param.SonstigRegelmJahrEnd2),0,Param.SonstigRegelmBetragJaehrl2*(1+Param.SonstigRegelmSteig2)^($A6-Param.SonstigRegelmJahrBeginn2)) -> 0 | F6: =IF(OR($A6<Param.SonstigRegelmJahrBeginn3,$A6>Param.SonstigRegelmJahrEnd3),0,Param.SonstigRegelmBetragJaehrl3*(1+Param.SonstigRegelmSteig3)^($A6-Param.SonstigRegelmJahrBeginn3)) -> 0 | G6: =IF(OR($A6<Param.SonstigRegelmJahrBeginn4,$A6>Param.SonstigRegelmJahrEnd4),0,Param.SonstigRegelmBetragJaehrl4*(1+Param.SonstigRegelmSteig4)^($A6-Param.SonstigRegelmJahrBeginn4)) -> 0 | H6: =IF(OR($A6<Param.SonstigRegelmJahrBeginn5,$A6>Param.SonstigRegelmJahrEnd5),0,Param.SonstigRegelmBetragJaehrl5*(1+Param.SonstigRegelmSteig5)^($A6-Param.SonstigRegelmJahrBeginn5)) -> 0 | I6: =IF(OR($A6<Param.SonstigRegelmJahrBeginn6,$A6>Param.SonstigRegelmJahrEnd6),0,Param.SonstigRegelmBetragJaehrl6*(1+Param.SonstigRegelmSteig6)^($A6-Param.SonstigRegelmJahrBeginn6)) -> 0 | J6: =IF(OR($A6<Param.SonstigRegelmJahrBeginn7,$A6>Param.SonstigRegelmJahrEnd7),0,Param.SonstigRegelmBetragJaehrl7*(1+Param.SonstigRegelmSteig7)^($A6-Param.SonstigRegelmJahrBeginn7)) -> 0 | K6: =IF(OR($A6<Param.SonstigRegelmJahrBeginn8,$A6>Param.SonstigRegelmJahrEnd8),0,Param.SonstigRegelmBetragJaehrl8*(1+Param.SonstigRegelmSteig8)^($A6-Param.SonstigRegelmJahrBeginn8)) -> 0 | L6: =IF(OR($A6<Param.SonstigRegelmJahrBeginn9,$A6>Param.SonstigRegelmJahrEnd9),0,Param.SonstigRegelmBetragJaehrl9*(1+Param.SonstigRegelmSteig9)^($A6-Param.SonstigRegelmJahrBeginn9)) -> 0 | M6: =IF(OR($A6<Param.SonstigRegelmJahrBeginn10,$A6>Param.SonstigRegelmJahrEnd10),0,Param.SonstigRegelmBetragJaehrl10*(1+Param.SonstigRegelmSteig10)^($A6-Param.SonstigRegelmJahrBeginn10)) -> 0 | N6: =MAX(0,C6-SUM(D6:M6)) -> 0 | O6: =IF(N6<=0,SUM(D6:M6)-C6,0) -> 0 | P6: =S6+AP6 -> 410925.37 | Q6: =IF(P6>0,S6/P6,0) -> 0.75133751 | R6: =IF(P6>0,AP6/P6,0) -> 0.24866249 | S6: =AL5 -> 308743.65 | T6: =AM5 -> 125243.65 | U6: =IF(A6<Param.FireStartjahr,Param.SparrateDepotMonatl*12*(1+Param.SparrateDynamikJaehrl)^($A6-Param.Startjahr),0) -> 6000 | V6: =IF(AND(Param.SonstigEinmaligKonto1="Depot",$A6=Param.SonstigEinmaligJahr1),Param.SonstigEinmaligBetrag1,0) -> 0 | W6: =IF(AND(Param.SonstigEinmaligKonto2="Depot",$A6=Param.SonstigEinmaligJahr2),Param.SonstigEinmaligBetrag2,0) -> 0 | X6: =IF(AND(Param.SonstigEinmaligKonto3="Depot",$A6=Param.SonstigEinmaligJahr3),Param.SonstigEinmaligBetrag3,0) -> 0 | Y6: =IF(AND(Param.SonstigEinmaligKonto4="Depot",$A6=Param.SonstigEinmaligJahr4),Param.SonstigEinmaligBetrag4,0) -> 0 | Z6: =IF(AND(Param.SonstigEinmaligKonto5="Depot",$A6=Param.SonstigEinmaligJahr5),Param.SonstigEinmaligBetrag5,0) -> 0 | AA6: =IF(AND(Param.SonstigEinmaligKonto6="Depot",$A6=Param.SonstigEinmaligJahr6),Param.SonstigEinmaligBetrag6,0) -> 0 | AB6: =IF(AND(Param.SonstigEinmaligKonto7="Depot",$A6=Param.SonstigEinmaligJahr7),Param.SonstigEinmaligBetrag7,0) -> 0 | AC6: =IF(AND(Param.SonstigEinmaligKonto8="Depot",$A6=Param.SonstigEinmaligJahr8),Param.SonstigEinmaligBetrag8,0) -> 0 | AD6: =IF(AND(Param.SonstigEinmaligKonto9="Depot",$A6=Param.SonstigEinmaligJahr9),Param.SonstigEinmaligBetrag9,0) -> 0 | AE6: =IF(AND(Param.SonstigEinmaligKonto10="Depot",$A6=Param.SonstigEinmaligJahr10),Param.SonstigEinmaligBetrag10,0) -> 0 | AF6: =Param.SparerPauschbetrag-BF6 -> 0 | AG6: =IF(AND(A6>=Param.FireStartjahr,S6>0),MIN(N6*Q6,S6),0) -> 0 | AH6: =IF(AG6<=0,0,IF(S6<=0,0,AG6/(1-MAX(0,((T6/S6)*(1-Param.Teilfreistellung)-MIN(AF6,AG6)/AG6)*Param.KapSt)))) -> 0 | AI6: =AH6-AG6 -> 0 | AJ6: =T6-AH6*(T6/S6) -> 125243.65 | AK6: =S6-AH6 -> 308743.65 | AL6: =FV(AO6,12,-(U6/12),-AK6,0) -> 324088.02 | AM6: =AJ6+AL6-AK6-U6 -> 134588.02 | AN6: =AM6/AL6 -> 0.4152823 | AO6: =(1+IF(AND(A6>=Param.DepotRenditeSpezBeginn1,A6<=Param.DepotRenditeSpezEnde1),Param.DepotRenditeSpezProz1,IF(AND(A6>=Param.DepotRenditeSpezBeginn2,A6<=Param.DepotRenditeSpezEnde2),Param.DepotRenditeSpezProz2,IF(AND(A6>=Param.DepotRenditeSpezBeginn3,A6<=Param.DepotRenditeSpezEnde3),Param.DepotRenditeSpezProz3,IF(AND(A6>=Param.DepotRenditeSpezBeginn4,A6<=Param.DepotRenditeSpezEnde4),Param.DepotRenditeSpezProz4,IF(AND(A6>=Param.DepotRenditeSpezBeginn5,A6<=Param.DepotRenditeSpezEnde5),Param.DepotRenditeSpezProz5,Param.DepotRenditeDefault))))))^(1/12)-1 -> 0.0024662698 | AP6: =BJ5 -> 102181.73 | AQ6: =IF(A6<Param.FireStartjahr,Param.SparrateFestgeldMonatl*12*(1+Param.SparrateDynamikJaehrl)^($A6-Param.Startjahr),0) -> 1800 | AR6: =O6 -> 0 | AS6: =IF(AND(Param.SonstigEinmaligKonto1="Festgeld",$A6=Param.SonstigEinmaligJahr1),Param.SonstigEinmaligBetrag1,0) -> 0 | AT6: =IF(AND(Param.SonstigEinmaligKonto2="Festgeld",$A6=Param.SonstigEinmaligJahr2),Param.SonstigEinmaligBetrag2,0) -> 0 | AU6: =IF(AND(Param.SonstigEinmaligKonto3="Festgeld",$A6=Param.SonstigEinmaligJahr3),Param.SonstigEinmaligBetrag3,0) -> 0 | AV6: =IF(AND(Param.SonstigEinmaligKonto4="Festgeld",$A6=Param.SonstigEinmaligJahr4),Param.SonstigEinmaligBetrag4,0) -> 0 | AW6: =IF(AND(Param.SonstigEinmaligKonto5="Festgeld",$A6=Param.SonstigEinmaligJahr5),Param.SonstigEinmaligBetrag5,0) -> 0 | AX6: =IF(AND(Param.SonstigEinmaligKonto6="Festgeld",$A6=Param.SonstigEinmaligJahr6),Param.SonstigEinmaligBetrag6,0) -> 0 | AY6: =IF(AND(Param.SonstigEinmaligKonto7="Festgeld",$A6=Param.SonstigEinmaligJahr7),Param.SonstigEinmaligBetrag7,0) -> 0 | AZ6: =IF(AND(Param.SonstigEinmaligKonto8="Festgeld",$A6=Param.SonstigEinmaligJahr8),Param.SonstigEinmaligBetrag8,0) -> 0 | BA6: =IF(AND(Param.SonstigEinmaligKonto9="Festgeld",$A6=Param.SonstigEinmaligJahr9),Param.SonstigEinmaligBetrag9,0) -> 0 | BB6: =IF(AND(Param.SonstigEinmaligKonto10="Festgeld",$A6=Param.SonstigEinmaligJahr10),Param.SonstigEinmaligBetrag10,0) -> 0 | BC6: =IF(AND(A6>=Param.FireStartjahr,AP6>0),MIN(N6*R6,AP6),0) -> 0 | BD6: =Param.FestgeldZinssatz -> 0.02 | BE6: =(AP6+SUM(AQ6:BB6)-BC6)*BD6 -> 2079.6345 | BF6: =IF(BE6>Param.SparerPauschbetrag,Param.SparerPauschbetrag,BE6) -> 1000 | BG6: =BE6-BF6 -> 1079.6345 | BH6: =BG6*Param.KapSt -> 284.75361 | BI6: =BE6-BH6 -> 1794.8809 | BJ6: =AP6+SUM(AQ6:BB6)-BC6+BI6 -> 105776.61 | BK6: =AL6+BJ6 -> 429864.62 | BL6: =BK6/(1+Param.Inflationsrate)^(A6-Param.Startjahr) -> 419380.12 | BM6: =IF(BK6<N6,A6,"") | BN6: =AH6+BC6 -> 0 | BO6: =SUM(AR6:BB6) -> 0 | BP6: =BN6+(-1*BO6) -> 0 | BQ6: =AI6+BH6 -> 284.75361 | BR6: =IF(BK6>0,BP6/BK6,0) -> 0
A7: =A6+1 -> 2028 | B7: =B5+(3-1) -> 32 | C7: =IF(A7<Param.FireStartjahr,0,Param.EntnahmeBetragStart*(1+Param.Inflationsrate)^(A7-Param.Startjahr)) -> 0 | D7: =IF(OR($A7<Param.SonstigRegelmJahrBeginn1,$A7>Param.SonstigRegelmJahrEnd1),0,Param.SonstigRegelmBetragJaehrl1*(1+Param.SonstigRegelmSteig1)^(A7-Param.SonstigRegelmJahrBeginn1)) -> 0 | E7: =IF(OR($A7<Param.SonstigRegelmJahrBeginn2,$A7>Param.SonstigRegelmJahrEnd2),0,Param.SonstigRegelmBetragJaehrl2*(1+Param.SonstigRegelmSteig2)^($A7-Param.SonstigRegelmJahrBeginn2)) -> 0 | F7: =IF(OR($A7<Param.SonstigRegelmJahrBeginn3,$A7>Param.SonstigRegelmJahrEnd3),0,Param.SonstigRegelmBetragJaehrl3*(1+Param.SonstigRegelmSteig3)^($A7-Param.SonstigRegelmJahrBeginn3)) -> 3600 | G7: =IF(OR($A7<Param.SonstigRegelmJahrBeginn4,$A7>Param.SonstigRegelmJahrEnd4),0,Param.SonstigRegelmBetragJaehrl4*(1+Param.SonstigRegelmSteig4)^($A7-Param.SonstigRegelmJahrBeginn4)) -> 0 | H7: =IF(OR($A7<Param.SonstigRegelmJahrBeginn5,$A7>Param.SonstigRegelmJahrEnd5),0,Param.SonstigRegelmBetragJaehrl5*(1+Param.SonstigRegelmSteig5)^($A7-Param.SonstigRegelmJahrBeginn5)) -> 0 | I7: =IF(OR($A7<Param.SonstigRegelmJahrBeginn6,$A7>Param.SonstigRegelmJahrEnd6),0,Param.SonstigRegelmBetragJaehrl6*(1+Param.SonstigRegelmSteig6)^($A7-Param.SonstigRegelmJahrBeginn6)) -> 0 | J7: =IF(OR($A7<Param.SonstigRegelmJahrBeginn7,$A7>Param.SonstigRegelmJahrEnd7),0,Param.SonstigRegelmBetragJaehrl7*(1+Param.SonstigRegelmSteig7)^($A7-Param.SonstigRegelmJahrBeginn7)) -> 0 | K7: =IF(OR($A7<Param.SonstigRegelmJahrBeginn8,$A7>Param.SonstigRegelmJahrEnd8),0,Param.SonstigRegelmBetragJaehrl8*(1+Param.SonstigRegelmSteig8)^($A7-Param.SonstigRegelmJahrBeginn8)) -> 0 | L7: =IF(OR($A7<Param.SonstigRegelmJahrBeginn9,$A7>Param.SonstigRegelmJahrEnd9),0,Param.SonstigRegelmBetragJaehrl9*(1+Param.SonstigRegelmSteig9)^($A7-Param.SonstigRegelmJahrBeginn9)) -> 0 | M7: =IF(OR($A7<Param.SonstigRegelmJahrBeginn10,$A7>Param.SonstigRegelmJahrEnd10),0,Param.SonstigRegelmBetragJaehrl10*(1+Param.SonstigRegelmSteig10)^($A7-Param.SonstigRegelmJahrBeginn10)) -> 0 | N7: =MAX(0,C7-SUM(D7:M7)) -> 0 | O7: =IF(N7<=0,SUM(D7:M7)-C7,0) -> 3600 | P7: =S7+AP7 -> 429864.62 | Q7: =IF(P7>0,S7/P7,0) -> 0.75393042 | R7: =IF(P7>0,AP7/P7,0) -> 0.24606958 | S7: =AL6 -> 324088.02 | T7: =AM6 -> 134588.02 | U7: =IF(A7<Param.FireStartjahr,Param.SparrateDepotMonatl*12*(1+Param.SparrateDynamikJaehrl)^($A7-Param.Startjahr),0) -> 6000 | V7: =IF(AND(Param.SonstigEinmaligKonto1="Depot",$A7=Param.SonstigEinmaligJahr1),Param.SonstigEinmaligBetrag1,0) -> 0 | W7: =IF(AND(Param.SonstigEinmaligKonto2="Depot",$A7=Param.SonstigEinmaligJahr2),Param.SonstigEinmaligBetrag2,0) -> 0 | X7: =IF(AND(Param.SonstigEinmaligKonto3="Depot",$A7=Param.SonstigEinmaligJahr3),Param.SonstigEinmaligBetrag3,0) -> 0 | Y7: =IF(AND(Param.SonstigEinmaligKonto4="Depot",$A7=Param.SonstigEinmaligJahr4),Param.SonstigEinmaligBetrag4,0) -> 0 | Z7: =IF(AND(Param.SonstigEinmaligKonto5="Depot",$A7=Param.SonstigEinmaligJahr5),Param.SonstigEinmaligBetrag5,0) -> 0 | AA7: =IF(AND(Param.SonstigEinmaligKonto6="Depot",$A7=Param.SonstigEinmaligJahr6),Param.SonstigEinmaligBetrag6,0) -> 0 | AB7: =IF(AND(Param.SonstigEinmaligKonto7="Depot",$A7=Param.SonstigEinmaligJahr7),Param.SonstigEinmaligBetrag7,0) -> 0 | AC7: =IF(AND(Param.SonstigEinmaligKonto8="Depot",$A7=Param.SonstigEinmaligJahr8),Param.SonstigEinmaligBetrag8,0) -> 0 | AD7: =IF(AND(Param.SonstigEinmaligKonto9="Depot",$A7=Param.SonstigEinmaligJahr9),Param.SonstigEinmaligBetrag9,0) -> 0 | AE7: =IF(AND(Param.SonstigEinmaligKonto10="Depot",$A7=Param.SonstigEinmaligJahr10),Param.SonstigEinmaligBetrag10,0) -> 0 | AF7: =Param.SparerPauschbetrag-BF7 -> 0 | AG7: =IF(AND(A7>=Param.FireStartjahr,S7>0),MIN(N7*Q7,S7),0) -> 0 | AH7: =IF(AG7<=0,0,IF(S7<=0,0,AG7/(1-MAX(0,((T7/S7)*(1-Param.Teilfreistellung)-MIN(AF7,AG7)/AG7)*Param.KapSt)))) -> 0 | AI7: =AH7-AG7 -> 0 | AJ7: =T7-AH7*(T7/S7) -> 134588.02 | AK7: =S7-AH7 -> 324088.02 | AL7: =FV(AO7,12,-(U7/12),-AK7,0) -> 339892.72 | AM7: =AJ7+AL7-AK7-U7 -> 144392.72 | AN7: =AM7/AL7 -> 0.42481851 | AO7: =(1+IF(AND(A7>=Param.DepotRenditeSpezBeginn1,A7<=Param.DepotRenditeSpezEnde1),Param.DepotRenditeSpezProz1,IF(AND(A7>=Param.DepotRenditeSpezBeginn2,A7<=Param.DepotRenditeSpezEnde2),Param.DepotRenditeSpezProz2,IF(AND(A7>=Param.DepotRenditeSpezBeginn3,A7<=Param.DepotRenditeSpezEnde3),Param.DepotRenditeSpezProz3,IF(AND(A7>=Param.DepotRenditeSpezBeginn4,A7<=Param.DepotRenditeSpezEnde4),Param.DepotRenditeSpezProz4,IF(AND(A7>=Param.DepotRenditeSpezBeginn5,A7<=Param.DepotRenditeSpezEnde5),Param.DepotRenditeSpezProz5,Param.DepotRenditeDefault))))))^(1/12)-1 -> 0.0024662698 | AP7: =BJ6 -> 105776.61 | AQ7: =IF(A7<Param.FireStartjahr,Param.SparrateFestgeldMonatl*12*(1+Param.SparrateDynamikJaehrl)^($A7-Param.Startjahr),0) -> 1800 | AR7: =O7 -> 3600 | AS7: =IF(AND(Param.SonstigEinmaligKonto1="Festgeld",$A7=Param.SonstigEinmaligJahr1),Param.SonstigEinmaligBetrag1,0) -> 0 | AT7: =IF(AND(Param.SonstigEinmaligKonto2="Festgeld",$A7=Param.SonstigEinmaligJahr2),Param.SonstigEinmaligBetrag2,0) -> 0 | AU7: =IF(AND(Param.SonstigEinmaligKonto3="Festgeld",$A7=Param.SonstigEinmaligJahr3),Param.SonstigEinmaligBetrag3,0) -> 0 | AV7: =IF(AND(Param.SonstigEinmaligKonto4="Festgeld",$A7=Param.SonstigEinmaligJahr4),Param.SonstigEinmaligBetrag4,0) -> 0 | AW7: =IF(AND(Param.SonstigEinmaligKonto5="Festgeld",$A7=Param.SonstigEinmaligJahr5),Param.SonstigEinmaligBetrag5,0) -> 0 | AX7: =IF(AND(Param.SonstigEinmaligKonto6="Festgeld",$A7=Param.SonstigEinmaligJahr6),Param.SonstigEinmaligBetrag6,0) -> 0 | AY7: =IF(AND(Param.SonstigEinmaligKonto7="Festgeld",$A7=Param.SonstigEinmaligJahr7),Param.SonstigEinmaligBetrag7,0) -> 0 | AZ7: =IF(AND(Param.SonstigEinmaligKonto8="Festgeld",$A7=Param.SonstigEinmaligJahr8),Param.SonstigEinmaligBetrag8,0) -> 0 | BA7: =IF(AND(Param.SonstigEinmaligKonto9="Festgeld",$A7=Param.SonstigEinmaligJahr9),Param.SonstigEinmaligBetrag9,0) -> 0 | BB7: =IF(AND(Param.SonstigEinmaligKonto10="Festgeld",$A7=Param.SonstigEinmaligJahr10),Param.SonstigEinmaligBetrag10,0) -> 0 | BC7: =IF(AND(A7>=Param.FireStartjahr,AP7>0),MIN(N7*R7,AP7),0) -> 0 | BD7: =Param.FestgeldZinssatz -> 0.02 | BE7: =(AP7+SUM(AQ7:BB7)-BC7)*BD7 -> 2223.5322 | BF7: =IF(BE7>Param.SparerPauschbetrag,Param.SparerPauschbetrag,BE7) -> 1000 | BG7: =BE7-BF7 -> 1223.5322 | BH7: =BG7*Param.KapSt -> 322.70661 | BI7: =BE7-BH7 -> 1900.8256 | BJ7: =AP7+SUM(AQ7:BB7)-BC7+BI7 -> 113077.43 | BK7: =AL7+BJ7 -> 452970.15 | BL7: =BK7/(1+Param.Inflationsrate)^(A7-Param.Startjahr) -> 431143.51 | BM7: =IF(BK7<N7,A7,"") | BN7: =AH7+BC7 -> 0 | BO7: =SUM(AR7:BB7) -> 3600 | BP7: =BN7+(-1*BO7) -> -3600 | BQ7: =AI7+BH7 -> 322.70661 | BR7: =IF(BK7>0,BP7/BK7,0) -> -0.0079475436
A8: =A7+1 -> 2029 | B8: =B5+(4-1) -> 33 | C8: =IF(A8<Param.FireStartjahr,0,Param.EntnahmeBetragStart*(1+Param.Inflationsrate)^(A8-Param.Startjahr)) -> 0 | D8: =IF(OR($A8<Param.SonstigRegelmJahrBeginn1,$A8>Param.SonstigRegelmJahrEnd1),0,Param.SonstigRegelmBetragJaehrl1*(1+Param.SonstigRegelmSteig1)^(A8-Param.SonstigRegelmJahrBeginn1)) -> 0 | E8: =IF(OR($A8<Param.SonstigRegelmJahrBeginn2,$A8>Param.SonstigRegelmJahrEnd2),0,Param.SonstigRegelmBetragJaehrl2*(1+Param.SonstigRegelmSteig2)^($A8-Param.SonstigRegelmJahrBeginn2)) -> 0 | F8: =IF(OR($A8<Param.SonstigRegelmJahrBeginn3,$A8>Param.SonstigRegelmJahrEnd3),0,Param.SonstigRegelmBetragJaehrl3*(1+Param.SonstigRegelmSteig3)^($A8-Param.SonstigRegelmJahrBeginn3)) -> 3636 | G8: =IF(OR($A8<Param.SonstigRegelmJahrBeginn4,$A8>Param.SonstigRegelmJahrEnd4),0,Param.SonstigRegelmBetragJaehrl4*(1+Param.SonstigRegelmSteig4)^($A8-Param.SonstigRegelmJahrBeginn4)) -> 0 | H8: =IF(OR($A8<Param.SonstigRegelmJahrBeginn5,$A8>Param.SonstigRegelmJahrEnd5),0,Param.SonstigRegelmBetragJaehrl5*(1+Param.SonstigRegelmSteig5)^($A8-Param.SonstigRegelmJahrBeginn5)) -> 0 | I8: =IF(OR($A8<Param.SonstigRegelmJahrBeginn6,$A8>Param.SonstigRegelmJahrEnd6),0,Param.SonstigRegelmBetragJaehrl6*(1+Param.SonstigRegelmSteig6)^($A8-Param.SonstigRegelmJahrBeginn6)) -> 0 | J8: =IF(OR($A8<Param.SonstigRegelmJahrBeginn7,$A8>Param.SonstigRegelmJahrEnd7),0,Param.SonstigRegelmBetragJaehrl7*(1+Param.SonstigRegelmSteig7)^($A8-Param.SonstigRegelmJahrBeginn7)) -> 0 | K8: =IF(OR($A8<Param.SonstigRegelmJahrBeginn8,$A8>Param.SonstigRegelmJahrEnd8),0,Param.SonstigRegelmBetragJaehrl8*(1+Param.SonstigRegelmSteig8)^($A8-Param.SonstigRegelmJahrBeginn8)) -> 0 | L8: =IF(OR($A8<Param.SonstigRegelmJahrBeginn9,$A8>Param.SonstigRegelmJahrEnd9),0,Param.SonstigRegelmBetragJaehrl9*(1+Param.SonstigRegelmSteig9)^($A8-Param.SonstigRegelmJahrBeginn9)) -> 0 | M8: =IF(OR($A8<Param.SonstigRegelmJahrBeginn10,$A8>Param.SonstigRegelmJahrEnd10),0,Param.SonstigRegelmBetragJaehrl10*(1+Param.SonstigRegelmSteig10)^($A8-Param.SonstigRegelmJahrBeginn10)) -> 0 | N8: =MAX(0,C8-SUM(D8:M8)) -> 0 | O8: =IF(N8<=0,SUM(D8:M8)-C8,0) -> 3636 | P8: =S8+AP8 -> 452970.15 | Q8: =IF(P8>0,S8/P8,0) -> 0.75036449 | R8: =IF(P8>0,AP8/P8,0) -> 0.24963551 | S8: =AL7 -> 339892.72 | T8: =AM7 -> 144392.72 | U8: =IF(A8<Param.FireStartjahr,Param.SparrateDepotMonatl*12*(1+Param.SparrateDynamikJaehrl)^($A8-Param.Startjahr),0) -> 6000 | V8: =IF(AND(Param.SonstigEinmaligKonto1="Depot",$A8=Param.SonstigEinmaligJahr1),Param.SonstigEinmaligBetrag1,0) -> 0 | W8: =IF(AND(Param.SonstigEinmaligKonto2="Depot",$A8=Param.SonstigEinmaligJahr2),Param.SonstigEinmaligBetrag2,0) -> 0 | X8: =IF(AND(Param.SonstigEinmaligKonto3="Depot",$A8=Param.SonstigEinmaligJahr3),Param.SonstigEinmaligBetrag3,0) -> 0 | Y8: =IF(AND(Param.SonstigEinmaligKonto4="Depot",$A8=Param.SonstigEinmaligJahr4),Param.SonstigEinmaligBetrag4,0) -> 0 | Z8: =IF(AND(Param.SonstigEinmaligKonto5="Depot",$A8=Param.SonstigEinmaligJahr5),Param.SonstigEinmaligBetrag5,0) -> 0 | AA8: =IF(AND(Param.SonstigEinmaligKonto6="Depot",$A8=Param.SonstigEinmaligJahr6),Param.SonstigEinmaligBetrag6,0) -> 0 | AB8: =IF(AND(Param.SonstigEinmaligKonto7="Depot",$A8=Param.SonstigEinmaligJahr7),Param.SonstigEinmaligBetrag7,0) -> 0 | AC8: =IF(AND(Param.SonstigEinmaligKonto8="Depot",$A8=Param.SonstigEinmaligJahr8),Param.SonstigEinmaligBetrag8,0) -> 0 | AD8: =IF(AND(Param.SonstigEinmaligKonto9="Depot",$A8=Param.SonstigEinmaligJahr9),Param.SonstigEinmaligBetrag9,0) -> 0 | AE8: =IF(AND(Param.SonstigEinmaligKonto10="Depot",$A8=Param.SonstigEinmaligJahr10),Param.SonstigEinmaligBetrag10,0) -> 0 | AF8: =Param.SparerPauschbetrag-BF8 -> 0 | AG8: =IF(AND(A8>=Param.FireStartjahr,S8>0),MIN(N8*Q8,S8),0) -> 0 | AH8: =IF(AG8<=0,0,IF(S8<=0,0,AG8/(1-MAX(0,((T8/S8)*(1-Param.Teilfreistellung)-MIN(AF8,AG8)/AG8)*Param.KapSt)))) -> 0 | AI8: =AH8-AG8 -> 0 | AJ8: =T8-AH8*(T8/S8) -> 144392.72 | AK8: =S8-AH8 -> 339892.72 | AL8: =FV(AO8,12,-(U8/12),-AK8,0) -> 366449.54 | AM8: =AJ8+AL8-AK8-U8 -> 164949.54 | AN8: =AM8/AL8 -> 0.45012894 | AO8: =(1+IF(AND(A8>=Param.DepotRenditeSpezBeginn1,A8<=Param.DepotRenditeSpezEnde1),Param.DepotRenditeSpezProz1,IF(AND(A8>=Param.DepotRenditeSpezBeginn2,A8<=Param.DepotRenditeSpezEnde2),Param.DepotRenditeSpezProz2,IF(AND(A8>=Param.DepotRenditeSpezBeginn3,A8<=Param.DepotRenditeSpezEnde3),Param.DepotRenditeSpezProz3,IF(AND(A8>=Param.DepotRenditeSpezBeginn4,A8<=Param.DepotRenditeSpezEnde4),Param.DepotRenditeSpezProz4,IF(AND(A8>=Param.DepotRenditeSpezBeginn5,A8<=Param.DepotRenditeSpezEnde5),Param.DepotRenditeSpezProz5,Param.DepotRenditeDefault))))))^(1/12)-1 -> 0.0048675506 | AP8: =BJ7 -> 113077.43 | AQ8: =IF(A8<Param.FireStartjahr,Param.SparrateFestgeldMonatl*12*(1+Param.SparrateDynamikJaehrl)^($A8-Param.Startjahr),0) -> 1800 | AR8: =O8 -> 3636 | AS8: =IF(AND(Param.SonstigEinmaligKonto1="Festgeld",$A8=Param.SonstigEinmaligJahr1),Param.SonstigEinmaligBetrag1,0) -> 0 | AT8: =IF(AND(Param.SonstigEinmaligKonto2="Festgeld",$A8=Param.SonstigEinmaligJahr2),Param.SonstigEinmaligBetrag2,0) -> 0 | AU8: =IF(AND(Param.SonstigEinmaligKonto3="Festgeld",$A8=Param.SonstigEinmaligJahr3),Param.SonstigEinmaligBetrag3,0) -> 0 | AV8: =IF(AND(Param.SonstigEinmaligKonto4="Festgeld",$A8=Param.SonstigEinmaligJahr4),Param.SonstigEinmaligBetrag4,0) -> 0 | AW8: =IF(AND(Param.SonstigEinmaligKonto5="Festgeld",$A8=Param.SonstigEinmaligJahr5),Param.SonstigEinmaligBetrag5,0) -> 0 | AX8: =IF(AND(Param.SonstigEinmaligKonto6="Festgeld",$A8=Param.SonstigEinmaligJahr6),Param.SonstigEinmaligBetrag6,0) -> 0 | AY8: =IF(AND(Param.SonstigEinmaligKonto7="Festgeld",$A8=Param.SonstigEinmaligJahr7),Param.SonstigEinmaligBetrag7,0) -> 0 | AZ8: =IF(AND(Param.SonstigEinmaligKonto8="Festgeld",$A8=Param.SonstigEinmaligJahr8),Param.SonstigEinmaligBetrag8,0) -> 0 | BA8: =IF(AND(Param.SonstigEinmaligKonto9="Festgeld",$A8=Param.SonstigEinmaligJahr9),Param.SonstigEinmaligBetrag9,0) -> 0 | BB8: =IF(AND(Param.SonstigEinmaligKonto10="Festgeld",$A8=Param.SonstigEinmaligJahr10),Param.SonstigEinmaligBetrag10,0) -> 0 | BC8: =IF(AND(A8>=Param.FireStartjahr,AP8>0),MIN(N8*R8,AP8),0) -> 0 | BD8: =Param.FestgeldZinssatz -> 0.02 | BE8: =(AP8+SUM(AQ8:BB8)-BC8)*BD8 -> 2370.2687 | BF8: =IF(BE8>Param.SparerPauschbetrag,Param.SparerPauschbetrag,BE8) -> 1000 | BG8: =BE8-BF8 -> 1370.2687 | BH8: =BG8*Param.KapSt -> 361.40836 | BI8: =BE8-BH8 -> 2008.8603 | BJ8: =AP8+SUM(AQ8:BB8)-BC8+BI8 -> 120522.29 | BK8: =AL8+BJ8 -> 486971.84 | BL8: =BK8/(1+Param.Inflationsrate)^(A8-Param.Startjahr) -> 452201.76 | BM8: =IF(BK8<N8,A8,"") | BN8: =AH8+BC8 -> 0 | BO8: =SUM(AR8:BB8) -> 3636 | BP8: =BN8+(-1*BO8) -> -3636 | BQ8: =AI8+BH8 -> 361.40836 | BR8: =IF(BK8>0,BP8/BK8,0) -> -0.0074665509
A9: =A8+1 -> 2030 | B9: =B5+(5-1) -> 34 | C9: =IF(A9<Param.FireStartjahr,0,Param.EntnahmeBetragStart*(1+Param.Inflationsrate)^(A9-Param.Startjahr)) -> 0 | D9: =IF(OR($A9<Param.SonstigRegelmJahrBeginn1,$A9>Param.SonstigRegelmJahrEnd1),0,Param.SonstigRegelmBetragJaehrl1*(1+Param.SonstigRegelmSteig1)^(A9-Param.SonstigRegelmJahrBeginn1)) -> 0 | E9: =IF(OR($A9<Param.SonstigRegelmJahrBeginn2,$A9>Param.SonstigRegelmJahrEnd2),0,Param.SonstigRegelmBetragJaehrl2*(1+Param.SonstigRegelmSteig2)^($A9-Param.SonstigRegelmJahrBeginn2)) -> 0 | F9: =IF(OR($A9<Param.SonstigRegelmJahrBeginn3,$A9>Param.SonstigRegelmJahrEnd3),0,Param.SonstigRegelmBetragJaehrl3*(1+Param.SonstigRegelmSteig3)^($A9-Param.SonstigRegelmJahrBeginn3)) -> 3672.36 | G9: =IF(OR($A9<Param.SonstigRegelmJahrBeginn4,$A9>Param.SonstigRegelmJahrEnd4),0,Param.SonstigRegelmBetragJaehrl4*(1+Param.SonstigRegelmSteig4)^($A9-Param.SonstigRegelmJahrBeginn4)) -> 0 | H9: =IF(OR($A9<Param.SonstigRegelmJahrBeginn5,$A9>Param.SonstigRegelmJahrEnd5),0,Param.SonstigRegelmBetragJaehrl5*(1+Param.SonstigRegelmSteig5)^($A9-Param.SonstigRegelmJahrBeginn5)) -> 0 | I9: =IF(OR($A9<Param.SonstigRegelmJahrBeginn6,$A9>Param.SonstigRegelmJahrEnd6),0,Param.SonstigRegelmBetragJaehrl6*(1+Param.SonstigRegelmSteig6)^($A9-Param.SonstigRegelmJahrBeginn6)) -> 0 | J9: =IF(OR($A9<Param.SonstigRegelmJahrBeginn7,$A9>Param.SonstigRegelmJahrEnd7),0,Param.SonstigRegelmBetragJaehrl7*(1+Param.SonstigRegelmSteig7)^($A9-Param.SonstigRegelmJahrBeginn7)) -> 0 | K9: =IF(OR($A9<Param.SonstigRegelmJahrBeginn8,$A9>Param.SonstigRegelmJahrEnd8),0,Param.SonstigRegelmBetragJaehrl8*(1+Param.SonstigRegelmSteig8)^($A9-Param.SonstigRegelmJahrBeginn8)) -> 0 | L9: =IF(OR($A9<Param.SonstigRegelmJahrBeginn9,$A9>Param.SonstigRegelmJahrEnd9),0,Param.SonstigRegelmBetragJaehrl9*(1+Param.SonstigRegelmSteig9)^($A9-Param.SonstigRegelmJahrBeginn9)) -> 0 | M9: =IF(OR($A9<Param.SonstigRegelmJahrBeginn10,$A9>Param.SonstigRegelmJahrEnd10),0,Param.SonstigRegelmBetragJaehrl10*(1+Param.SonstigRegelmSteig10)^($A9-Param.SonstigRegelmJahrBeginn10)) -> 0 | N9: =MAX(0,C9-SUM(D9:M9)) -> 0 | O9: =IF(N9<=0,SUM(D9:M9)-C9,0) -> 3672.36 | P9: =S9+AP9 -> 486971.84 | Q9: =IF(P9>0,S9/P9,0) -> 0.75250664 | R9: =IF(P9>0,AP9/P9,0) -> 0.24749336 | S9: =AL8 -> 366449.54 | T9: =AM8 -> 164949.54 | U9: =IF(A9<Param.FireStartjahr,Param.SparrateDepotMonatl*12*(1+Param.SparrateDynamikJaehrl)^($A9-Param.Startjahr),0) -> 6000 | V9: =IF(AND(Param.SonstigEinmaligKonto1="Depot",$A9=Param.SonstigEinmaligJahr1),Param.SonstigEinmaligBetrag1,0) -> 0 | W9: =IF(AND(Param.SonstigEinmaligKonto2="Depot",$A9=Param.SonstigEinmaligJahr2),Param.SonstigEinmaligBetrag2,0) -> 0 | X9: =IF(AND(Param.SonstigEinmaligKonto3="Depot",$A9=Param.SonstigEinmaligJahr3),Param.SonstigEinmaligBetrag3,0) -> 0 | Y9: =IF(AND(Param.SonstigEinmaligKonto4="Depot",$A9=Param.SonstigEinmaligJahr4),Param.SonstigEinmaligBetrag4,0) -> 0 | Z9: =IF(AND(Param.SonstigEinmaligKonto5="Depot",$A9=Param.SonstigEinmaligJahr5),Param.SonstigEinmaligBetrag5,0) -> 0 | AA9: =IF(AND(Param.SonstigEinmaligKonto6="Depot",$A9=Param.SonstigEinmaligJahr6),Param.SonstigEinmaligBetrag6,0) -> 0 | AB9: =IF(AND(Param.SonstigEinmaligKonto7="Depot",$A9=Param.SonstigEinmaligJahr7),Param.SonstigEinmaligBetrag7,0) -> 0 | AC9: =IF(AND(Param.SonstigEinmaligKonto8="Depot",$A9=Param.SonstigEinmaligJahr8),Param.SonstigEinmaligBetrag8,0) -> 0 | AD9: =IF(AND(Param.SonstigEinmaligKonto9="Depot",$A9=Param.SonstigEinmaligJahr9),Param.SonstigEinmaligBetrag9,0) -> 0 | AE9: =IF(AND(Param.SonstigEinmaligKonto10="Depot",$A9=Param.SonstigEinmaligJahr10),Param.SonstigEinmaligBetrag10,0) -> 0 | AF9: =Param.SparerPauschbetrag-BF9 -> 0 | AG9: =IF(AND(A9>=Param.FireStartjahr,S9>0),MIN(N9*Q9,S9),0) -> 0 | AH9: =IF(AG9<=0,0,IF(S9<=0,0,AG9/(1-MAX(0,((T9/S9)*(1-Param.Teilfreistellung)-MIN(AF9,AG9)/AG9)*Param.KapSt)))) -> 0 | AI9: =AH9-AG9 -> 0 | AJ9: =T9-AH9*(T9/S9) -> 164949.54 | AK9: =S9-AH9 -> 366449.54 | AL9: =FV(AO9,12,-(U9/12),-AK9,0) -> 387216.75 | AM9: =AJ9+AL9-AK9-U9 -> 179716.75 | AN9: =AM9/AL9 -> 0.46412442 | AO9: =(1+IF(AND(A9>=Param.DepotRenditeSpezBeginn1,A9<=Param.DepotRenditeSpezEnde1),Param.DepotRenditeSpezProz1,IF(AND(A9>=Param.DepotRenditeSpezBeginn2,A9<=Param.DepotRenditeSpezEnde2),Param.DepotRenditeSpezProz2,IF(AND(A9>=Param.DepotRenditeSpezBeginn3,A9<=Param.DepotRenditeSpezEnde3),Param.DepotRenditeSpezProz3,IF(AND(A9>=Param.DepotRenditeSpezBeginn4,A9<=Param.DepotRenditeSpezEnde4),Param.DepotRenditeSpezProz4,IF(AND(A9>=Param.DepotRenditeSpezBeginn5,A9<=Param.DepotRenditeSpezEnde5),Param.DepotRenditeSpezProz5,Param.DepotRenditeDefault))))))^(1/12)-1 -> 0.0032737398 | AP9: =BJ8 -> 120522.29 | AQ9: =IF(A9<Param.FireStartjahr,Param.SparrateFestgeldMonatl*12*(1+Param.SparrateDynamikJaehrl)^($A9-Param.Startjahr),0) -> 1800 | AR9: =O9 -> 3672.36 | AS9: =IF(AND(Param.SonstigEinmaligKonto1="Festgeld",$A9=Param.SonstigEinmaligJahr1),Param.SonstigEinmaligBetrag1,0) -> 0 | AT9: =IF(AND(Param.SonstigEinmaligKonto2="Festgeld",$A9=Param.SonstigEinmaligJahr2),Param.SonstigEinmaligBetrag2,0) -> -25000 | AU9: =IF(AND(Param.SonstigEinmaligKonto3="Festgeld",$A9=Param.SonstigEinmaligJahr3),Param.SonstigEinmaligBetrag3,0) -> 0 | AV9: =IF(AND(Param.SonstigEinmaligKonto4="Festgeld",$A9=Param.SonstigEinmaligJahr4),Param.SonstigEinmaligBetrag4,0) -> 0 | AW9: =IF(AND(Param.SonstigEinmaligKonto5="Festgeld",$A9=Param.SonstigEinmaligJahr5),Param.SonstigEinmaligBetrag5,0) -> 0 | AX9: =IF(AND(Param.SonstigEinmaligKonto6="Festgeld",$A9=Param.SonstigEinmaligJahr6),Param.SonstigEinmaligBetrag6,0) -> 0 | AY9: =IF(AND(Param.SonstigEinmaligKonto7="Festgeld",$A9=Param.SonstigEinmaligJahr7),Param.SonstigEinmaligBetrag7,0) -> 0 | AZ9: =IF(AND(Param.SonstigEinmaligKonto8="Festgeld",$A9=Param.SonstigEinmaligJahr8),Param.SonstigEinmaligBetrag8,0) -> 0 | BA9: =IF(AND(Param.SonstigEinmaligKonto9="Festgeld",$A9=Param.SonstigEinmaligJahr9),Param.SonstigEinmaligBetrag9,0) -> 0 | BB9: =IF(AND(Param.SonstigEinmaligKonto10="Festgeld",$A9=Param.SonstigEinmaligJahr10),Param.SonstigEinmaligBetrag10,0) -> 0 | BC9: =IF(AND(A9>=Param.FireStartjahr,AP9>0),MIN(N9*R9,AP9),0) -> 0 | BD9: =Param.FestgeldZinssatz -> 0.02 | BE9: =(AP9+SUM(AQ9:BB9)-BC9)*BD9 -> 2019.8931 | BF9: =IF(BE9>Param.SparerPauschbetrag,Param.SparerPauschbetrag,BE9) -> 1000 | BG9: =BE9-BF9 -> 1019.8931 | BH9: =BG9*Param.KapSt -> 268.9968 | BI9: =BE9-BH9 -> 1750.8963 | BJ9: =AP9+SUM(AQ9:BB9)-BC9+BI9 -> 102745.55 | BK9: =AL9+BJ9 -> 489962.3 | BL9: =BK9/(1+Param.Inflationsrate)^(A9-Param.Startjahr) -> 443881.66 | BM9: =IF(BK9<N9,A9,"") | BN9: =AH9+BC9 -> 0 | BO9: =SUM(AR9:BB9) -> -21327.64 | BP9: =BN9+(-1*BO9) -> 21327.64 | BQ9: =AI9+BH9 -> 268.9968 | BR9: =IF(BK9>0,BP9/BK9,0) -> 0.043529145
A10: =A9+1 -> 2031 | B10: =B5+(6-1) -> 35 | C10: =IF(A10<Param.FireStartjahr,0,Param.EntnahmeBetragStart*(1+Param.Inflationsrate)^(A10-Param.Startjahr)) -> 0 | D10: =IF(OR($A10<Param.SonstigRegelmJahrBeginn1,$A10>Param.SonstigRegelmJahrEnd1),0,Param.SonstigRegelmBetragJaehrl1*(1+Param.SonstigRegelmSteig1)^(A10-Param.SonstigRegelmJahrBeginn1)) -> 0 | E10: =IF(OR($A10<Param.SonstigRegelmJahrBeginn2,$A10>Param.SonstigRegelmJahrEnd2),0,Param.SonstigRegelmBetragJaehrl2*(1+Param.SonstigRegelmSteig2)^($A10-Param.SonstigRegelmJahrBeginn2)) -> 0 | F10: =IF(OR($A10<Param.SonstigRegelmJahrBeginn3,$A10>Param.SonstigRegelmJahrEnd3),0,Param.SonstigRegelmBetragJaehrl3*(1+Param.SonstigRegelmSteig3)^($A10-Param.SonstigRegelmJahrBeginn3)) -> 3709.0836 | G10: =IF(OR($A10<Param.SonstigRegelmJahrBeginn4,$A10>Param.SonstigRegelmJahrEnd4),0,Param.SonstigRegelmBetragJaehrl4*(1+Param.SonstigRegelmSteig4)^($A10-Param.SonstigRegelmJahrBeginn4)) -> 0 | H10: =IF(OR($A10<Param.SonstigRegelmJahrBeginn5,$A10>Param.SonstigRegelmJahrEnd5),0,Param.SonstigRegelmBetragJaehrl5*(1+Param.SonstigRegelmSteig5)^($A10-Param.SonstigRegelmJahrBeginn5)) -> 0 | I10: =IF(OR($A10<Param.SonstigRegelmJahrBeginn6,$A10>Param.SonstigRegelmJahrEnd6),0,Param.SonstigRegelmBetragJaehrl6*(1+Param.SonstigRegelmSteig6)^($A10-Param.SonstigRegelmJahrBeginn6)) -> 0 | J10: =IF(OR($A10<Param.SonstigRegelmJahrBeginn7,$A10>Param.SonstigRegelmJahrEnd7),0,Param.SonstigRegelmBetragJaehrl7*(1+Param.SonstigRegelmSteig7)^($A10-Param.SonstigRegelmJahrBeginn7)) -> 0 | K10: =IF(OR($A10<Param.SonstigRegelmJahrBeginn8,$A10>Param.SonstigRegelmJahrEnd8),0,Param.SonstigRegelmBetragJaehrl8*(1+Param.SonstigRegelmSteig8)^($A10-Param.SonstigRegelmJahrBeginn8)) -> 0 | L10: =IF(OR($A10<Param.SonstigRegelmJahrBeginn9,$A10>Param.SonstigRegelmJahrEnd9),0,Param.SonstigRegelmBetragJaehrl9*(1+Param.SonstigRegelmSteig9)^($A10-Param.SonstigRegelmJahrBeginn9)) -> 0 | M10: =IF(OR($A10<Param.SonstigRegelmJahrBeginn10,$A10>Param.SonstigRegelmJahrEnd10),0,Param.SonstigRegelmBetragJaehrl10*(1+Param.SonstigRegelmSteig10)^($A10-Param.SonstigRegelmJahrBeginn10)) -> 0 | N10: =MAX(0,C10-SUM(D10:M10)) -> 0 | O10: =IF(N10<=0,SUM(D10:M10)-C10,0) -> 3709.0836 | P10: =S10+AP10 -> 489962.3 | Q10: =IF(P10>0,S10/P10,0) -> 0.79029907 | R10: =IF(P10>0,AP10/P10,0) -> 0.20970093 | S10: =AL9 -> 387216.75 | T10: =AM9 -> 179716.75 | U10: =IF(A10<Param.FireStartjahr,Param.SparrateDepotMonatl*12*(1+Param.SparrateDynamikJaehrl)^($A10-Param.Startjahr),0) -> 6000 | V10: =IF(AND(Param.SonstigEinmaligKonto1="Depot",$A10=Param.SonstigEinmaligJahr1),Param.SonstigEinmaligBetrag1,0) -> 0 | W10: =IF(AND(Param.SonstigEinmaligKonto2="Depot",$A10=Param.SonstigEinmaligJahr2),Param.SonstigEinmaligBetrag2,0) -> 0 | X10: =IF(AND(Param.SonstigEinmaligKonto3="Depot",$A10=Param.SonstigEinmaligJahr3),Param.SonstigEinmaligBetrag3,0) -> 0 | Y10: =IF(AND(Param.SonstigEinmaligKonto4="Depot",$A10=Param.SonstigEinmaligJahr4),Param.SonstigEinmaligBetrag4,0) -> 0 | Z10: =IF(AND(Param.SonstigEinmaligKonto5="Depot",$A10=Param.SonstigEinmaligJahr5),Param.SonstigEinmaligBetrag5,0) -> 0 | AA10: =IF(AND(Param.SonstigEinmaligKonto6="Depot",$A10=Param.SonstigEinmaligJahr6),Param.SonstigEinmaligBetrag6,0) -> 0 | AB10: =IF(AND(Param.SonstigEinmaligKonto7="Depot",$A10=Param.SonstigEinmaligJahr7),Param.SonstigEinmaligBetrag7,0) -> 0 | AC10: =IF(AND(Param.SonstigEinmaligKonto8="Depot",$A10=Param.SonstigEinmaligJahr8),Param.SonstigEinmaligBetrag8,0) -> 0 | AD10: =IF(AND(Param.SonstigEinmaligKonto9="Depot",$A10=Param.SonstigEinmaligJahr9),Param.SonstigEinmaligBetrag9,0) -> 0 | AE10: =IF(AND(Param.SonstigEinmaligKonto10="Depot",$A10=Param.SonstigEinmaligJahr10),Param.SonstigEinmaligBetrag10,0) -> 0 | AF10: =Param.SparerPauschbetrag-BF10 -> 0 | AG10: =IF(AND(A10>=Param.FireStartjahr,S10>0),MIN(N10*Q10,S10),0) -> 0 | AH10: =IF(AG10<=0,0,IF(S10<=0,0,AG10/(1-MAX(0,((T10/S10)*(1-Param.Teilfreistellung)-MIN(AF10,AG10)/AG10)*Param.KapSt)))) -> 0 | AI10: =AH10-AG10 -> 0 | AJ10: =T10-AH10*(T10/S10) -> 179716.75 | AK10: =S10-AH10 -> 387216.75 | AL10: =FV(AO10,12,-(U10/12),-AK10,0) -> 408814.64 | AM10: =AJ10+AL10-AK10-U10 -> 195314.64 | AN10: =AM10/AL10 -> 0.47775842 | AO10: =(1+IF(AND(A10>=Param.DepotRenditeSpezBeginn1,A10<=Param.DepotRenditeSpezEnde1),Param.DepotRenditeSpezProz1,IF(AND(A10>=Param.DepotRenditeSpezBeginn2,A10<=Param.DepotRenditeSpezEnde2),Param.DepotRenditeSpezProz2,IF(AND(A10>=Param.DepotRenditeSpezBeginn3,A10<=Param.DepotRenditeSpezEnde3),Param.DepotRenditeSpezProz3,IF(AND(A10>=Param.DepotRenditeSpezBeginn4,A10<=Param.DepotRenditeSpezEnde4),Param.DepotRenditeSpezProz4,IF(AND(A10>=Param.DepotRenditeSpezBeginn5,A10<=Param.DepotRenditeSpezEnde5),Param.DepotRenditeSpezProz5,Param.DepotRenditeDefault))))))^(1/12)-1 -> 0.0032737398 | AP10: =BJ9 -> 102745.55 | AQ10: =IF(A10<Param.FireStartjahr,Param.SparrateFestgeldMonatl*12*(1+Param.SparrateDynamikJaehrl)^($A10-Param.Startjahr),0) -> 1800 | AR10: =O10 -> 3709.0836 | AS10: =IF(AND(Param.SonstigEinmaligKonto1="Festgeld",$A10=Param.SonstigEinmaligJahr1),Param.SonstigEinmaligBetrag1,0) -> 0 | AT10: =IF(AND(Param.SonstigEinmaligKonto2="Festgeld",$A10=Param.SonstigEinmaligJahr2),Param.SonstigEinmaligBetrag2,0) -> 0 | AU10: =IF(AND(Param.SonstigEinmaligKonto3="Festgeld",$A10=Param.SonstigEinmaligJahr3),Param.SonstigEinmaligBetrag3,0) -> 0 | AV10: =IF(AND(Param.SonstigEinmaligKonto4="Festgeld",$A10=Param.SonstigEinmaligJahr4),Param.SonstigEinmaligBetrag4,0) -> 0 | AW10: =IF(AND(Param.SonstigEinmaligKonto5="Festgeld",$A10=Param.SonstigEinmaligJahr5),Param.SonstigEinmaligBetrag5,0) -> 0 | AX10: =IF(AND(Param.SonstigEinmaligKonto6="Festgeld",$A10=Param.SonstigEinmaligJahr6),Param.SonstigEinmaligBetrag6,0) -> 0 | AY10: =IF(AND(Param.SonstigEinmaligKonto7="Festgeld",$A10=Param.SonstigEinmaligJahr7),Param.SonstigEinmaligBetrag7,0) -> 0 | AZ10: =IF(AND(Param.SonstigEinmaligKonto8="Festgeld",$A10=Param.SonstigEinmaligJahr8),Param.SonstigEinmaligBetrag8,0) -> 0 | BA10: =IF(AND(Param.SonstigEinmaligKonto9="Festgeld",$A10=Param.SonstigEinmaligJahr9),Param.SonstigEinmaligBetrag9,0) -> 0 | BB10: =IF(AND(Param.SonstigEinmaligKonto10="Festgeld",$A10=Param.SonstigEinmaligJahr10),Param.SonstigEinmaligBetrag10,0) -> 0 | BC10: =IF(AND(A10>=Param.FireStartjahr,AP10>0),MIN(N10*R10,AP10),0) -> 0 | BD10: =Param.FestgeldZinssatz -> 0.02 | BE10: =(AP10+SUM(AQ10:BB10)-BC10)*BD10 -> 2165.0927 | BF10: =IF(BE10>Param.SparerPauschbetrag,Param.SparerPauschbetrag,BE10) -> 1000 | BG10: =BE10-BF10 -> 1165.0927 | BH10: =BG10*Param.KapSt -> 307.29319 | BI10: =BE10-BH10 -> 1857.7995 | BJ10: =AP10+SUM(AQ10:BB10)-BC10+BI10 -> 110112.43 | BK10: =AL10+BJ10 -> 518927.07 | BL10: =BK10/(1+Param.Inflationsrate)^(A10-Param.Startjahr) -> 458655.92 | BM10: =IF(BK10<N10,A10,"") | BN10: =AH10+BC10 -> 0 | BO10: =SUM(AR10:BB10) -> 3709.0836 | BP10: =BN10+(-1*BO10) -> -3709.0836 | BQ10: =AI10+BH10 -> 307.29319 | BR10: =IF(BK10>0,BP10/BK10,0) -> -0.0071476009
